<?xml version="1.0" ?>
<mujoco model="panda">
    <compiler angle="radian" meshdir="meshes/" />
    
    <option timestep="0.002">
        <flag contact="disable" energy="enable"/>
    </option>

    <asset>
        <!-- Materials -->
        <material name="white" rgba="1 1 1 1" />
        <material name="gray" rgba="0.5 0.5 0.5 1" />
        <material name="joint_chrome" rgba="0.7 0.7 0.7 1" />
        
        <!-- Simple geometric primitives for visualization -->
        <mesh name="link0" file="link0.stl" />
        <mesh name="link1" file="link1.stl" />
        <mesh name="link2" file="link2.stl" />
        <mesh name="link3" file="link3.stl" />
        <mesh name="link4" file="link4.stl" />
        <mesh name="link5" file="link5.stl" />
        <mesh name="link6" file="link6.stl" />
        <mesh name="link7" file="link7.stl" />
        <mesh name="hand" file="hand.stl" />
        <mesh name="finger" file="finger.stl" />
    </asset>

    <worldbody>
        <light diffuse=".8 .8 .8" dir="0 -.15 -1" directional="true" pos="0 0 4.0" specular="0.3 0.3 0.3"/>
        <light diffuse=".8 .8 .8" dir="0 -.15 1" directional="true" pos="0 0 -4.0" specular="0.3 0.3 0.3"/>
        
        <!-- Robot base -->
        <body name="panda_link0" pos="0 0 0">
            <inertial pos="0 0 0" mass="4.970684" diaginertia="0.70337 0.70661 0.0091170" />
            <geom type="mesh" material="gray" mesh="link0" />
            
            <body name="panda_link1" pos="0 0 0.333">
                <joint name="panda_joint1" pos="0 0 0" axis="0 0 1" limited="true" range="-2.8973 2.8973" />
                <inertial pos="0 0 0" mass="4.970684" diaginertia="0.70337 0.70661 0.0091170" />
                <geom type="mesh" material="white" mesh="link1" />
                
                <body name="panda_link2" pos="0 0 0" quat="0.707107 -0.707107 0 0">
                    <joint name="panda_joint2" pos="0 0 0" axis="0 0 1" limited="true" range="-1.7628 1.7628" />
                    <inertial pos="-0.0324958 -0.0675823 -0.0418915" mass="0.646926" diaginertia="0.0079620 0.0079620 0.0079620" />
                    <geom type="mesh" material="white" mesh="link2" />
                    
                    <body name="panda_link3" pos="0 -0.316 0" quat="0.707107 0.707107 0 0">
                        <joint name="panda_joint3" pos="0 0 0" axis="0 0 1" limited="true" range="-2.8973 2.8973" />
                        <inertial pos="0.0375960 0.0349008 -0.0440875" mass="3.228604" diaginertia="0.0037440 0.0037440 0.0037440" />
                        <geom type="mesh" material="white" mesh="link3" />
                        
                        <body name="panda_link4" pos="0.0825 0 0" quat="0.707107 0.707107 0 0">
                            <joint name="panda_joint4" pos="0 0 0" axis="0 0 1" limited="true" range="-3.0718 -0.0698" />
                            <inertial pos="-0.0381353 0.0433282 0.0263291" mass="3.587895" diaginertia="0.0047310 0.0047310 0.0047310" />
                            <geom type="mesh" material="white" mesh="link4" />
                            
                            <body name="panda_link5" pos="-0.0825 0.384 0" quat="0.707107 -0.707107 0 0">
                                <joint name="panda_joint5" pos="0 0 0" axis="0 0 1" limited="true" range="-2.8973 2.8973" />
                                <inertial pos="0.0244869 -0.0435397 0.0188339" mass="1.225946" diaginertia="0.0035550 0.0035550 0.0035550" />
                                <geom type="mesh" material="white" mesh="link5" />
                                
                                <body name="panda_link6" pos="0 0 0" quat="0.707107 0.707107 0 0">
                                    <joint name="panda_joint6" pos="0 0 0" axis="0 0 1" limited="true" range="-0.0175 3.7525" />
                                    <inertial pos="0.0454768 0.0304835 -0.0141898" mass="1.666555" diaginertia="0.0042880 0.0042880 0.0042880" />
                                    <geom type="mesh" material="white" mesh="link6" />
                                    
                                    <body name="panda_link7" pos="0.088 0 0" quat="0.707107 0.707107 0 0">
                                        <joint name="panda_joint7" pos="0 0 0" axis="0 0 1" limited="true" range="-2.8973 2.8973" />
                                        <inertial pos="0.0107343 -0.0060158 0.0147671" mass="0.735522" diaginertia="0.0004380 0.0004380 0.0004380" />
                                        <geom type="mesh" material="white" mesh="link7" />
                                        
                                        <body name="panda_hand" pos="0 0 0.107" quat="0.92388 0 0 -0.382683">
                                            <inertial pos="0 0 0.0" mass="0.73" diaginertia="0.001 0.0025 0.0017" />
                                            <geom type="mesh" material="gray" mesh="hand" />
                                            
                                            <!-- Fingers -->
                                            <body name="panda_leftfinger" pos="0 0 0.0584">
                                                <joint name="panda_finger_joint1" type="slide" axis="0 1 0" range="0 0.04" />
                                                <geom type="mesh" material="gray" mesh="finger" />
                                            </body>
                                            <body name="panda_rightfinger" pos="0 0 0.0584">
                                                <joint name="panda_finger_joint2" type="slide" axis="0 -1 0" range="0 0.04" />
                                                <geom type="mesh" material="gray" mesh="finger" />
                                            </body>
                                        </body>
                                    </body>
                                </body>
                            </body>
                        </body>
                    </body>
                </body>
            </body>
        </body>
    </worldbody>

    <actuator>
        <!-- Position actuators -->
        <position name="panda_joint1_position" joint="panda_joint1" kp="100" />
        <position name="panda_joint2_position" joint="panda_joint2" kp="100" />
        <position name="panda_joint3_position" joint="panda_joint3" kp="100" />
        <position name="panda_joint4_position" joint="panda_joint4" kp="100" />
        <position name="panda_joint5_position" joint="panda_joint5" kp="100" />
        <position name="panda_joint6_position" joint="panda_joint6" kp="100" />
        <position name="panda_joint7_position" joint="panda_joint7" kp="100" />
        <position name="panda_finger_joint1_position" joint="panda_finger_joint1" kp="100" />
        <position name="panda_finger_joint2_position" joint="panda_finger_joint2" kp="100" />
        
        <!-- Velocity actuators -->
        <velocity name="panda_joint1_velocity" joint="panda_joint1" kv="10" />
        <velocity name="panda_joint2_velocity" joint="panda_joint2" kv="10" />
        <velocity name="panda_joint3_velocity" joint="panda_joint3" kv="10" />
        <velocity name="panda_joint4_velocity" joint="panda_joint4" kv="10" />
        <velocity name="panda_joint5_velocity" joint="panda_joint5" kv="10" />
        <velocity name="panda_joint6_velocity" joint="panda_joint6" kv="10" />
        <velocity name="panda_joint7_velocity" joint="panda_joint7" kv="10" />
    </actuator>

    <sensor>
        <jointpos name="panda_joint1_sensor" joint="panda_joint1" />
        <jointpos name="panda_joint2_sensor" joint="panda_joint2" />
        <jointpos name="panda_joint3_sensor" joint="panda_joint3" />
        <jointpos name="panda_joint4_sensor" joint="panda_joint4" />
        <jointpos name="panda_joint5_sensor" joint="panda_joint5" />
        <jointpos name="panda_joint6_sensor" joint="panda_joint6" />
        <jointpos name="panda_joint7_sensor" joint="panda_joint7" />
    </sensor>
</mujoco>
